Workbook

Sheet Inicio
B2: RACKSA ECUADOR · Base de prospectos y CRM nacional
B3: Preparado el 25/10/2026 · 24 provincias · 93 empresas
B5: Cómo usarlo
B6: 1. «Prospectos»: empresas con bodega por provincia, con sector, necesidad probable y producto sugerido. Prioridad A = empezar aquí.
B7: 2. Para cada empresa, abre el enlace «Buscar decisor en LinkedIn» y busca Jefe de Logística, Bodega, Operaciones o Compras.
B8: 3. «Mensajes»: elige el sector y el canal (LinkedIn, WhatsApp o correo) y personaliza [Nombre] y [Empresa].
B9: 4. «CRM»: registra cada contacto. Cambia el Estado con la lista, anota la última llamada y el próximo paso con fecha.
B10: La fila se pinta en rojo si el próximo paso está vencido y en amarillo si es en los próximos 3 días.
B11: 5. «Resumen»: cuenta automática por estado y por región.
B13: Ritmo sugerido
B14: • 10 contactos nuevos por día (5 LinkedIn + 5 correo/WhatsApp). Seguimiento a los 3 días y a los 7 días. Tras 3 intentos sin respuesta: «Perdido / sin respuesta» y reintentar en 3 meses.
B15: • Al enviar una proforma, cambia el estado y programa la llamada de seguimiento a los 3 días.
... B28: • Los mensajes solo usan datos aprobados (ficha técnica de rack selectivo, perchas 500 kg/nivel, stock para entrega inmediata, cobertura nacional). Nada se envía sin tu revisión.

Sheet Resumen
A1: Embudo de ventas (CRM) | D1: Prospectos por región
A2: Estado | B2: Empresas | D2: Región | E2: Empresas
A3: Por contactar | B3: =COUNTIF(CRM!$J:$J,A3) | D3: Costa | E3: =COUNTIF(Prospectos!$C:$C,D3)
A4: Contactado | B4: =COUNTIF(CRM!$J:$J,A4) | D4: Sierra | E4: =COUNTIF(Prospectos!$C:$C,D4)
A5: Respondió / interesado | B5: =COUNTIF(CRM!$J:$J,A5) | D5: Amazonía | E5: =COUNTIF(Prospectos!$C:$C,D5)
A6: Visita agendada | B6: =COUNTIF(CRM!$J:$J,A6) | D6: Insular | E6: =COUNTIF(Prospectos!$C:$C,D6)
A7: Levantamiento en bodega | B7: =COUNTIF(CRM!$J:$J,A7)
A8: Proforma enviada | B8: =COUNTIF(CRM!$J:$J,A8) | D8: Prospectos por provincia
A9: Negociación | B9: =COUNTIF(CRM!$J:$J,A9) | D9: Guayas | E9: =COUNTIF(Prospectos!$D:$D,D9)
A10: Ganado | B10: =COUNTIF(CRM!$J:$J,A10) | D10: Pichincha | E10: =COUNTIF(Prospectos!$D:$D,D10)
A11: Perdido / sin respuesta | B11: =COUNTIF(CRM!$J:$J,A11) | D11: Manabí | E11: =COUNTIF(Prospectos!$D:$D,D11)
A12: No aplica | B12: =COUNTIF(CRM!$J:$J,A12) | D12: Azuay | E12: =COUNTIF(Prospectos!$D:$D,D12)
A13: Monto en proformas (sin IVA) | B13: =SUM(CRM!R:R) | D13: Loja | E13: =COUNTIF(Prospectos!$D:$D,D13)
A14: Seguimientos vencidos | B14: =COUNTIFS(CRM!O:O,"<"&TODAY(),CRM!O:O,"<>") | D14: Imbabura | E14: =COUNTIF(Prospectos!$D:$D,D14)
D15: Tungurahua | E15: =COUNTIF(Prospectos!$D:$D,D15)
D16: Chimborazo | E16: =COUNTIF(Prospectos!$D:$D,D16)
D17: El Oro | E17: =COUNTIF(Prospectos!$D:$D,D17)
D18: Pastaza | E18: =COUNTIF(Prospectos!$D:$D,D18)
D19: Cotopaxi | E19: =COUNTIF(Prospectos!$D:$D,D19)
D20: Zamora Chinchipe | E20: =COUNTIF(Prospectos!$D:$D,D20)
D21: Cañar | E21: =COUNTIF(Prospectos!$D:$D,D21)
D22: Bolívar | E22: =COUNTIF(Prospectos!$D:$D,D22)
D23: Orellana | E23: =COUNTIF(Prospectos!$D:$D,D23)
D24: Santa Elena | E24: =COUNTIF(Prospectos!$D:$D,D24)
D25: Carchi | E25: =COUNTIF(Prospectos!$D:$D,D25)
D26: Galápagos | E26: =COUNTIF(Prospectos!$D:$D,D26)
... D32: Los Ríos | E32: =COUNTIF(Prospectos!$D:$D,D32)

Sheet Prospectos
A1: ID | B1: Prioridad | C1: Región | D1: Provincia | E1: Ciudad | F1: Empresa | G1: Sector | H1: Grupo de mensaje | I1: Necesidad probable | J1: Producto Racksa sugerido | K1: Sitio web | L1: Teléfono público | M1: Correo público | N1: Página de contacto | O1: Dirección / sedes | P1: Buscar decisor en LinkedIn | Q1: Ver en Google Maps | R1: Fuente | S1: Contacto verificado
A2: P001 | B2: A | C2: Costa | D2: El Oro | E2: Machala | F2: Farmamia | G2: Farmacia / retail | H2: Farmacéutica | I2: Bodega central de farmacias | J2: Perchas de picking + rack selectivo | P2: Abrir | Q2: Abrir | R2: Primicias: mayor venta de El Oro 2023 | S2: Pendiente
A3: P002 | B3: A | C3: Costa | D3: Guayas | E3: Guayaquil | F3: Agripac | G3: Agroinsumos / distribución | H3: Agroindustria y acuacultura | I3: Bodegas de agroquímicos y sacos (pallets) | J3: Rack selectivo para insumos y empaque | K3: https://www.agripac.com.ec | L3: (04) 370 3870 / 256 0400 | M3: info@agripac.com.ec | N3: https://agripac.com.ec/contactanos/ | O3: General Córdova 623 y Padre Solano, Guayaquil | P3: Abrir | Q3: Abrir | R3: Web oficial | S3: Sí, web oficial 25-oct-2026
A4: P003 | B4: A | C4: Costa | D4: Guayas | E4: Guayaquil | F4: Comandato | G4: Retail electrodomésticos | H4: Retail y supermercados | I4: Bodegas de electrodomésticos | J4: Rack selectivo para CD + perchas de picking | K4: https://www.comandato.com | P4: Abrir | Q4: Abrir | R4: Web oficial | S4: Pendiente
A5: P004 | B5: A | C5: Costa | D5: Guayas | E5: Guayaquil | F5: Corporación El Rosado (Mi Comisariato, Ferrisariato) | G5: Retail / supermercados | H5: Retail y supermercados | I5: Centros de distribución y bodegas de tiendas | J5: Rack selectivo para CD + perchas de picking | K5: https://www.elrosado.com | P5: Abrir | Q5: Abrir | R5: Primicias: mayor venta de Guayas | S5: Pendiente
A6: P005 | B6: A | C6: Costa | D6: Guayas | E6: Guayaquil | F6: Difare (Cruz Azul, Pharmacy's) | G6: Farmacéutica / distribución | H6: Farmacéutica | I6: CD farmacéutico, picking por unidades | J6: Perchas de picking + rack selectivo | K6: https://www.difare.com.ec | N6: https://difare.com.ec/contacto | P6: Abrir | Q6: Abrir | R6: Web oficial | S6: Pendiente
A7: P006 | B7: A | C7: Costa | D7: Guayas | E7: Guayaquil | F7: Ecuaquímica | G7: Agroinsumos / químicos | H7: Agroindustria y acuacultura | I7: Bodegas de químicos y productos veterinarios | J7: Rack selectivo para insumos y empaque | K7: https://www.ecuaquimica.com.ec | L7: (04) 550 5040 | N7: https://ecuaquimica.com.ec/contactenos/ | O7: Av. José Santiago Castillo y Juan Tanca Marengo, Guayaquil | P7: Abrir | Q7: Abrir | R7: Web oficial | S7: Sí, web oficial 25-oct-2026
A8: P007 | B8: A | C8: Costa | D8: Guayas | E8: Guayaquil | F8: Industrial Pesquera Santa Priscila | G8: Camaronera / exportadora | H8: Agroindustria y acuacultura | I8: Bodegas de insumos, empaque y producto | J8: Rack selectivo para insumos y empaque | K8: https://www.santapriscila.com | P8: Abrir | Q8: Abrir | R8: Web oficial | S8: Pendiente
A9: P008 | B9: A | C9: Costa | D9: Guayas | E9: Guayaquil | F9: Tiendas Industriales Asociadas (TIA) | G9: Retail / supermercados | H9: Retail y supermercados | I9: Red nacional de tiendas y CD | J9: Rack selectivo para CD + perchas de picking | K9: https://www.tia.com.ec | P9: Abrir | Q9: Abrir | R9: Web oficial | S9: Pendiente
A10: P009 | B10: A | C10: Costa | D10: Guayas | E10: Guayaquil | F10: Tonicorp | G10: Lácteos / alimentos | H10: Alimentos, bebidas y consumo | I10: Cámaras y bodegas de producto | J10: Rack selectivo para pallets | K10: https://www.tonicorp.com | P10: Abrir | Q10: Abrir | R10: Web oficial | S10: Pendiente
A11: P010 | B11: A | C11: Costa | D11: Manabí | E11: Manta | F11: Dipac Manta | G11: Acero / ferretería | H11: Ferretería, acero y construcción | I11: Almacenaje de perfiles (cantilever) | J11: Rack selectivo + rack para perfiles largos (consultar) | K11: https://www.dipacmanta.com | L11: Durán (04) 501 0600 · Cuenca (07) 500 6060 · Ambato (03) 500 0550 · Babahoyo (05) 500 1880 | M11: info@dipacmanta.com | N11: https://dipacmanta.com/contacto/ | O11: Sucursales en Durán, Cuenca, Ambato, Babahoyo | P11: Abrir | Q11: Abrir | R11: Web oficial | S11: Sí, web oficial 25-oct-2026
A12: P011 | B12: A | C12: Costa | D12: Manabí | E12: Portoviejo | F12: Farmacias Santamartha | G12: Farmacia / retail | H12: Farmacéutica | I12: Bodega central de farmacias | J12: Perchas de picking + rack selectivo | K12: https://www.farmaciassantamartha.com | P12: Abrir | Q12: Abrir | R12: El Diario: top 25 Manabí | S12: Pendiente
A13: P012 | B13: A | C13: Costa | D13: Manabí | E13: Montecristi | F13: La Fabril | G13: Consumo masivo (aceites, jabones) | H13: Alimentos, bebidas y consumo | I13: Bodegas de PT y materia prima | J13: Rack selectivo para pallets | K13: https://www.lafabril.com.ec | P13: Abrir | Q13: Abrir | R13: Primicias: mayor venta de Manabí | S13: Pendiente
A14: P013 | B14: A | C14: Sierra | D14: Azuay | E14: Cuenca | F14: Cartopel | G14: Manufactura cartón | H14: Manufactura | I14: Bodegas de bobinas y PT | J14: Rack selectivo para materia prima y PT | K14: https://www.cartopel.com | L14: (07) 286 0600 ext. 7110 · GYE (04) 500 1111 ext. 4110 · UIO (02) 248 4169 · Machala (07) 399 2496 | N14: https://www.cartopel.com/contactos/ | O14: Cuenca: Parque Industrial · Machala: CD DICA | P14: Abrir | Q14: Abrir | R14: Primicias / El Mercurio: top Azuay | S14: Sí, web oficial 25-oct-2026
A15: P014 | B15: A | C15: Sierra | D15: Azuay | E15: Cuenca | F15: Gerardo Ortiz e Hijos (Coral Hipermercados) | G15: Retail / ferretería | H15: Retail y supermercados | I15: CD de hipermercados | J15: Rack selectivo para CD + perchas de picking | K15: https://www.gerardoortiz.com | P15: Abrir | Q15: Abrir | R15: Web oficial | S15: Pendiente
A16: P015 | B16: A | C16: Sierra | D16: Azuay | E16: Cuenca | F16: Graiman | G16: Cerámica / construcción | H16: Ferretería, acero y construcción | I16: Almacenaje de cerámica en pallets | J16: Rack selectivo + rack para perfiles largos (consultar) | K16: https://www.graiman.com | L16: WhatsApp +593 99 758 5127 | N16: https://www.graiman.com/contacto | P16: Abrir | Q16: Abrir | R16: Web oficial | S16: Sí, web oficial 25-oct-2026
A17: P016 | B17: A | C17: Sierra | D17: Azuay | E17: Cuenca | F17: Indurama (Induglob) | G17: Electrodomésticos | H17: Manufactura | I17: Bodegas de PT y repuestos | J17: Rack selectivo para materia prima y PT | K17: https://www.indurama.com | L17: WhatsApp +593 97 977 7052 | N17: https://www.indurama.com/contact-us | P17: Abrir | Q17: Abrir | R17: Primicias: mayor venta de Azuay 2023 | S17: Sí, web oficial 25-oct-2026
A18: P017 | B18: A | C18: Sierra | D18: Azuay | E18: Cuenca | F18: Marcimex | G18: Retail electrodomésticos | H18: Retail y supermercados | I18: CD y bodegas de tiendas | J18: Rack selectivo para CD + perchas de picking | K18: https://www.marcimex.com | P18: Abrir | Q18: Abrir | R18: El Mercurio: top 5 Azuay | S18: Pendiente
A19: P018 | B19: A | C19: Sierra | D19: Carchi | E19: Tulcán | F19: Distribuidora Suprice | G19: Distribución alimentos y bebidas | H19: Alimentos, bebidas y consumo | I19: CD de distribución | J19: Rack selectivo para pallets | P19: Abrir | Q19: Abrir | R19: Primicias: mayor venta de Carchi | S19: Pendiente
A20: P019 | B20: A | C20: Sierra | D20: Cotopaxi | E20: Lasso | F20: Novacero | G20: Acero | H20: Ferretería, acero y construcción | I20: Almacenaje de perfiles, cubiertas, varilla | J20: Rack selectivo + rack para perfiles largos (consultar) | K20: https://www.novacero.com | L20: (03) 299 8400 Planta Lasso · (04) 380 0600 GYE · (02) 398 1900 UIO · 1800 668 223 | M20: ventasgye@novacero.com / ventasuio@novacero.com | N20: https://www.novacero.com/contacto/ | O20: Planta Lasso, Panamericana Norte Km 16 (portal proveedores: proveedores.novacero.com) | P20: Abrir | Q20: Abrir | R20: Primicias: mayor venta de Cotopaxi | S20: Sí, web oficial 25-oct-2026
A21: P020 | B21: A | C21: Sierra | D21: Loja | E21: Loja | F21: Industrial Lojana de Especerías (ILE) | G21: Alimentos | H21: Alimentos, bebidas y consumo | I21: Bodegas de PT y materia prima | J21: Rack selectivo para pallets | K21: https://www.ile.com.ec | P21: Abrir | Q21: Abrir | R21: Primicias: mayor venta de Loja 2023 | S21: Pendiente
A22: P021 | B22: A | C22: Sierra | D22: Pichincha | E22: Quito | F22: Corporación Favorita (Supermaxi, Kywi) | G22: Retail / supermercados | H22: Retail y supermercados | I22: Centros de distribución nacionales | J22: Rack selectivo para CD + perchas de picking | K22: https://www.corporacionfavorita.com | P22: Abrir | Q22: Abrir | R22: Primicias: mayor venta de Pichincha | S22: Pendiente
A23: P022 | B23: A | C23: Sierra | D23: Pichincha | E23: Quito | F23: Corporación GPF (Fybeca, SanaSana) | G23: Farmacéutica / retail | H23: Farmacéutica | I23: CD farmacéutico | J23: Perchas de picking + rack selectivo | K23: https://www.corporaciongpf.com | P23: Abrir | Q23: Abrir | R23: Web oficial | S23: Pendiente
A24: P023 | B24: A | C24: Sierra | D24: Pichincha | E24: Quito | F24: Farmaenlace (Medicity, Farmacias Económicas) | G24: Farmacéutica / retail | H24: Farmacéutica | I24: CD farmacéutico | J24: Perchas de picking + rack selectivo | K24: https://www.farmaenlace.com | L24: (02) 299 3100 | M24: servicioalcliente@farmaenlace.com | O24: Av. Portugal E12-72 y Eloy Alfaro, Quito | P24: Abrir | Q24: Abrir | R24: Web oficial | S24: Sí, web oficial 25-oct-2026
A25: P024 | B25: A | C25: Sierra | D25: Pichincha | E25: Quito | F25: Kywi | G25: Ferretería | H25: Ferretería, acero y construcción | I25: Bodegas y CD de ferretería | J25: Rack selectivo + rack para perfiles largos (consultar) | K25: https://www.kywi.com.ec | P25: Abrir | Q25: Abrir | R25: Web oficial | S25: Pendiente
A26: P025 | B26: A | C26: Sierra | D26: Pichincha | E26: Quito | F26: Leterago del Ecuador | G26: Distribución farmacéutica | H26: Farmacéutica | I26: CD farmacéutico | J26: Perchas de picking + rack selectivo | K26: https://www.leterago.com.ec | P26: Abrir | Q26: Abrir | R26: Web oficial | S26: Pendiente
A27: P026 | B27: A | C27: Sierra | D27: Pichincha | E27: Quito | F27: Pronaca | G27: Alimentos | H27: Alimentos, bebidas y consumo | I27: Bodegas y cámaras en varias provincias | J27: Rack selectivo para pallets | K27: https://www.pronaca.com | N27: https://pronaca.com/contactanos/ | P27: Abrir | Q27: Abrir | R27: Web oficial | S27: Pendiente
A28: P027 | B28: A | C28: Sierra | D28: Pichincha | E28: Quito | F28: Quifatex | G28: Distribución farmacéutica y consumo | H28: Farmacéutica | I28: CD de distribución nacional | J28: Perchas de picking + rack selectivo | K28: https://www.quifatex.com | L28: 02 299 5200 / 1800 784 328 / WhatsApp 099 722 9922 | M28: comunicaciones@quifatex.com | N28: https://quifatex.com/es/contactanos | O28: CD Quito: Panamericana Norte Km 14,5 · CD Guayaquil: Pascuales Km 14,5 vía Daule | P28: Abrir | Q28: Abrir | R28: Web oficial | S28: Sí, web oficial 25-oct-2026
A29: P028 | B29: A | C29: Sierra | D29: Tungurahua | E29: Ambato | F29: Ambacar | G29: Automotriz | H29: Automotriz y repuestos | I29: Bodegas de repuestos (perchas) | J29: Perchas de picking para repuestos | K29: https://www.ambacar.ec | P29: Abrir | Q29: Abrir | R29: Primicias: mayor venta de Tungurahua | S29: Pendiente
A30: P029 | B30: A | C30: Sierra | D30: Tungurahua | E30: Ambato | F30: Megaprofer | G30: Ferretería | H30: Ferretería, acero y construcción | I30: Bodegas de materiales | J30: Rack selectivo + rack para perfiles largos (consultar) | K30: https://www.megaprofer.com | L30: (03) 282 7470 Ambato · (02) 382 7470 · 099 497 3073 | M30: info@megaprofer.com | N30: https://www.megaprofer.com/contact.html | O30: Matriz Quito; sucursales Ambato y Guayaquil | P30: Abrir | Q30: Abrir | R30: Web oficial | S30: Sí, web oficial 25-oct-2026
A31: P030 | B31: A | C31: Sierra | D31: Tungurahua | E31: Ambato | F31: Plasticaucho Industrial | G31: Manufactura calzado | H31: Manufactura | I31: Bodegas de PT y materia prima | J31: Rack selectivo para materia prima y PT | K31: https://www.plasticaucho.com | P31: Abrir | Q31: Abrir | R31: Web oficial | S31: Pendiente
A32: P031 | B32: A | C32: Amazonía | D32: Sucumbíos | E32: Lago Agrio | F32: Román Hermanos | G32: Logística | H32: Logística y courier | I32: Bodegas logísticas | J32: Rack selectivo + perchas + mezzanine (consultar) | P32: Abrir | Q32: Abrir | R32: Primicias: mayor venta de Sucumbíos | S32: Pendiente
A33: P032 | B33: A | C33: Amazonía | D33: Zamora Chinchipe | E33: El Pangui | F33: Ecuacorriente (Mirador) | G33: Minería | H33: Minería, petróleo y energía | I33: Bodegas de repuestos e insumos mineros | J33: Perchas para repuestos + rack selectivo | K33: https://www.ecuacorriente.com | P33: Abrir | Q33: Abrir | R33: Primicias: mayor venta de Zamora Chinchipe | S33: Pendiente
A34: P033 | B34: B | C34: Costa | D34: El Oro | E34: Machala | F34: Promaoro | G34: Camaronera / procesadora | H34: Agroindustria y acuacultura | I34: Bodegas de empaque y PT | J34: Rack selectivo para insumos y empaque | P34: Abrir | Q34: Abrir | R34: Primicias: top El Oro | S34: Pendiente
A35: P034 | B35: B | C35: Costa | D35: Esmeraldas | E35: Esmeraldas | F35: Palmar de Los Esteros (Palesema) | G35: Palma aceitera | H35: Agroindustria y acuacultura | I35: Bodegas de insumos | J35: Rack selectivo para insumos y empaque | K35: https://www.palesema.com | P35: Abrir | Q35: Abrir | R35: Primicias: mayor venta de Esmeraldas | S35: Pendiente
A36: P035 | B36: B | C36: Costa | D36: Guayas | E36: Guayaquil | F36: Almacenes De Prati | G36: Retail / moda | H36: Retail y supermercados | I36: CD de mercadería, perchas de picking | J36: Rack selectivo para CD + perchas de picking | K36: https://www.deprati.com.ec | P36: Abrir | Q36: Abrir | R36: Web oficial | S36: Pendiente
A37: P036 | B37: B | C37: Costa | D37: Guayas | E37: Guayaquil | F37: Almacenes La Ganga | G37: Retail electrodomésticos | H37: Retail y supermercados | I37: Bodegas de electrodomésticos | J37: Rack selectivo para CD + perchas de picking | K37: https://www.almaceneslaganga.com | P37: Abrir | Q37: Abrir | R37: Web oficial | S37: Pendiente
A38: P037 | B38: B | C38: Costa | D38: Guayas | E38: Guayaquil | F38: Artefacta | G38: Retail electrodomésticos | H38: Retail y supermercados | I38: Bodegas de electrodomésticos | J38: Rack selectivo para CD + perchas de picking | K38: https://www.artefacta.com | P38: Abrir | Q38: Abrir | R38: Web oficial | S38: Pendiente
A39: P038 | B39: B | C39: Costa | D39: Guayas | E39: Guayaquil | F39: Cervecería Nacional | G39: Bebidas | H39: Alimentos, bebidas y consumo | I39: Bodegas de producto terminado y envases | J39: Rack selectivo para pallets | K39: https://www.cervecerianacional.ec | P39: Abrir | Q39: Abrir | R39: Web oficial | S39: Pendiente
A40: P039 | B40: B | C40: Costa | D40: Guayas | E40: Guayaquil | F40: Contecon Guayaquil | G40: Puerto / logística | H40: Logística y courier | I40: Bodegas y patios logísticos | J40: Rack selectivo + perchas + mezzanine (consultar) | K40: https://www.cgsa.com.ec | P40: Abrir | Q40: Abrir | R40: Web oficial | S40: Pendiente
...

Sheet CRM
A1: ID | B1: Empresa | C1: Provincia | D1: Prioridad | E1: Contacto (nombre) | F1: Cargo | G1: Teléfono / WhatsApp | H1: Correo | I1: Canal | J1: Estado | K1: Fecha 1er contacto | L1: Última llamada / contacto | M1: Resultado de la última llamada | N1: Próximo paso | O1: Fecha próximo paso | P1: Días sin contacto | Q1: N.º proforma | R1: Monto proforma (sin IVA) | S1: Notas | T1: ✉️ Abrir correo listo | U1: ↩️ Correo de seguimiento | V1: 📅 Agendar seguimiento
A2: P001 | B2: =IFERROR(INDEX(Prospectos!$F:$F,MATCH(A2,Prospectos!$A:$A,0)),"") | C2: =IFERROR(INDEX(Prospectos!$D:$D,MATCH(A2,Prospectos!$A:$A,0)),"") | D2: =IFERROR(INDEX(Prospectos!$B:$B,MATCH(A2,Prospectos!$A:$A,0)),"") | J2: Por contactar | P2: =IF(L2="","",TODAY()-L2) | T2: ✉️ Abrir correo | U2: ↩️ Seguimiento | V2: =IF(A2="","",HYPERLINK("https://calendar.google.com/calendar/render?action=TEMPLATE&text="&"Racksa%3A%20"&SUBSTITUTE(SUBSTITUTE(SUBSTITUTE(LEFT(B2,45),"&","y")," ","%20"),"#","")&"%20-%20seguimiento"&"&dates="&YEAR(IF(O2="",TODAY()+3,O2))&RIGHT("0"&MONTH(IF(O2="",TODAY()+3,O2)),2)&RIGHT("0"&DAY(IF(O2="",TODAY()+3,O2)),2)&"/"&YEAR(IF(O2="",TODAY()+4,O2+1))&RIGHT("0"&MONTH(IF(O2="",TODAY()+4,O2+1)),2)&RIGHT("0"&DAY(IF(O2="",TODAY()+4,O2+1)),2),"📅 Agendar"))
A3: P002 | B3: =IFERROR(INDEX(Prospectos!$F:$F,MATCH(A3,Prospectos!$A:$A,0)),"") | C3: =IFERROR(INDEX(Prospectos!$D:$D,MATCH(A3,Prospectos!$A:$A,0)),"") | D3: =IFERROR(INDEX(Prospectos!$B:$B,MATCH(A3,Prospectos!$A:$A,0)),"") | H3: info@agripac.com.ec | I3: Correo | J3: Por contactar | P3: =IF(L3="","",TODAY()-L3) | T3: ✉️ Abrir correo | U3: ↩️ Seguimiento | V3: =IF(A3="","",HYPERLINK("https://calendar.google.com/calendar/render?action=TEMPLATE&text="&"Racksa%3A%20"&SUBSTITUTE(SUBSTITUTE(SUBSTITUTE(LEFT(B3,45),"&","y")," ","%20"),"#","")&"%20-%20seguimiento"&"&dates="&YEAR(IF(O3="",TODAY()+3,O3))&RIGHT("0"&MONTH(IF(O3="",TODAY()+3,O3)),2)&RIGHT("0"&DAY(IF(O3="",TODAY()+3,O3)),2)&"/"&YEAR(IF(O3="",TODAY()+4,O3+1))&RIGHT("0"&MONTH(IF(O3="",TODAY()+4,O3+1)),2)&RIGHT("0"&DAY(IF(O3="",TODAY()+4,O3+1)),2),"📅 Agendar"))
A4: P003 | B4: =IFERROR(INDEX(Prospectos!$F:$F,MATCH(A4,Prospectos!$A:$A,0)),"") | C4: =IFERROR(INDEX(Prospectos!$D:$D,MATCH(A4,Prospectos!$A:$A,0)),"") | D4: =IFERROR(INDEX(Prospectos!$B:$B,MATCH(A4,Prospectos!$A:$A,0)),"") | J4: Por contactar | P4: =IF(L4="","",TODAY()-L4) | T4: ✉️ Abrir correo | U4: ↩️ Seguimiento | V4: =IF(A4="","",HYPERLINK("https://calendar.google.com/calendar/render?action=TEMPLATE&text="&"Racksa%3A%20"&SUBSTITUTE(SUBSTITUTE(SUBSTITUTE(LEFT(B4,45),"&","y")," ","%20"),"#","")&"%20-%20seguimiento"&"&dates="&YEAR(IF(O4="",TODAY()+3,O4))&RIGHT("0"&MONTH(IF(O4="",TODAY()+3,O4)),2)&RIGHT("0"&DAY(IF(O4="",TODAY()+3,O4)),2)&"/"&YEAR(IF(O4="",TODAY()+4,O4+1))&RIGHT("0"&MONTH(IF(O4="",TODAY()+4,O4+1)),2)&RIGHT("0"&DAY(IF(O4="",TODAY()+4,O4+1)),2),"📅 Agendar"))
A5: P004 | B5: =IFERROR(INDEX(Prospectos!$F:$F,MATCH(A5,Prospectos!$A:$A,0)),"") | C5: =IFERROR(INDEX(Prospectos!$D:$D,MATCH(A5,Prospectos!$A:$A,0)),"") | D5: =IFERROR(INDEX(Prospectos!$B:$B,MATCH(A5,Prospectos!$A:$A,0)),"") | J5: Por contactar | P5: =IF(L5="","",TODAY()-L5) | T5: ✉️ Abrir correo | U5: ↩️ Seguimiento | V5: =IF(A5="","",HYPERLINK("https://calendar.google.com/calendar/render?action=TEMPLATE&text="&"Racksa%3A%20"&SUBSTITUTE(SUBSTITUTE(SUBSTITUTE(LEFT(B5,45),"&","y")," ","%20"),"#","")&"%20-%20seguimiento"&"&dates="&YEAR(IF(O5="",TODAY()+3,O5))&RIGHT("0"&MONTH(IF(O5="",TODAY()+3,O5)),2)&RIGHT("0"&DAY(IF(O5="",TODAY()+3,O5)),2)&"/"&YEAR(IF(O5="",TODAY()+4,O5+1))&RIGHT("0"&MONTH(IF(O5="",TODAY()+4,O5+1)),2)&RIGHT("0"&DAY(IF(O5="",TODAY()+4,O5+1)),2),"📅 Agendar"))
A6: P005 | B6: =IFERROR(INDEX(Prospectos!$F:$F,MATCH(A6,Prospectos!$A:$A,0)),"") | C6: =IFERROR(INDEX(Prospectos!$D:$D,MATCH(A6,Prospectos!$A:$A,0)),"") | D6: =IFERROR(INDEX(Prospectos!$B:$B,MATCH(A6,Prospectos!$A:$A,0)),"") | J6: Por contactar | P6: =IF(L6="","",TODAY()-L6) | T6: ✉️ Abrir correo | U6: ↩️ Seguimiento | V6: =IF(A6="","",HYPERLINK("https://calendar.google.com/calendar/render?action=TEMPLATE&text="&"Racksa%3A%20"&SUBSTITUTE(SUBSTITUTE(SUBSTITUTE(LEFT(B6,45),"&","y")," ","%20"),"#","")&"%20-%20seguimiento"&"&dates="&YEAR(IF(O6="",TODAY()+3,O6))&RIGHT("0"&MONTH(IF(O6="",TODAY()+3,O6)),2)&RIGHT("0"&DAY(IF(O6="",TODAY()+3,O6)),2)&"/"&YEAR(IF(O6="",TODAY()+4,O6+1))&RIGHT("0"&MONTH(IF(O6="",TODAY()+4,O6+1)),2)&RIGHT("0"&DAY(IF(O6="",TODAY()+4,O6+1)),2),"📅 Agendar"))
A7: P006 | B7: =IFERROR(INDEX(Prospectos!$F:$F,MATCH(A7,Prospectos!$A:$A,0)),"") | C7: =IFERROR(INDEX(Prospectos!$D:$D,MATCH(A7,Prospectos!$A:$A,0)),"") | D7: =IFERROR(INDEX(Prospectos!$B:$B,MATCH(A7,Prospectos!$A:$A,0)),"") | J7: Por contactar | P7: =IF(L7="","",TODAY()-L7) | T7: ✉️ Abrir correo | U7: ↩️ Seguimiento | V7: =IF(A7="","",HYPERLINK("https://calendar.google.com/calendar/render?action=TEMPLATE&text="&"Racksa%3A%20"&SUBSTITUTE(SUBSTITUTE(SUBSTITUTE(LEFT(B7,45),"&","y")," ","%20"),"#","")&"%20-%20seguimiento"&"&dates="&YEAR(IF(O7="",TODAY()+3,O7))&RIGHT("0"&MONTH(IF(O7="",TODAY()+3,O7)),2)&RIGHT("0"&DAY(IF(O7="",TODAY()+3,O7)),2)&"/"&YEAR(IF(O7="",TODAY()+4,O7+1))&RIGHT("0"&MONTH(IF(O7="",TODAY()+4,O7+1)),2)&RIGHT("0"&DAY(IF(O7="",TODAY()+4,O7+1)),2),"📅 Agendar"))
A8: P007 | B8: =IFERROR(INDEX(Prospectos!$F:$F,MATCH(A8,Prospectos!$A:$A,0)),"") | C8: =IFERROR(INDEX(Prospectos!$D:$D,MATCH(A8,Prospectos!$A:$A,0)),"") | D8: =IFERROR(INDEX(Prospectos!$B:$B,MATCH(A8,Prospectos!$A:$A,0)),"") | J8: Por contactar | P8: =IF(L8="","",TODAY()-L8) | T8: ✉️ Abrir correo | U8: ↩️ Seguimiento | V8: =IF(A8="","",HYPERLINK("https://calendar.google.com/calendar/render?action=TEMPLATE&text="&"Racksa%3A%20"&SUBSTITUTE(SUBSTITUTE(SUBSTITUTE(LEFT(B8,45),"&","y")," ","%20"),"#","")&"%20-%20seguimiento"&"&dates="&YEAR(IF(O8="",TODAY()+3,O8))&RIGHT("0"&MONTH(IF(O8="",TODAY()+3,O8)),2)&RIGHT("0"&DAY(IF(O8="",TODAY()+3,O8)),2)&"/"&YEAR(IF(O8="",TODAY()+4,O8+1))&RIGHT("0"&MONTH(IF(O8="",TODAY()+4,O8+1)),2)&RIGHT("0"&DAY(IF(O8="",TODAY()+4,O8+1)),2),"📅 Agendar"))
A9: P008 | B9: =IFERROR(INDEX(Prospectos!$F:$F,MATCH(A9,Prospectos!$A:$A,0)),"") | C9: =IFERROR(INDEX(Prospectos!$D:$D,MATCH(A9,Prospectos!$A:$A,0)),"") | D9: =IFERROR(INDEX(Prospectos!$B:$B,MATCH(A9,Prospectos!$A:$A,0)),"") | J9: Por contactar | P9: =IF(L9="","",TODAY()-L9) | T9: ✉️ Abrir correo | U9: ↩️ Seguimiento | V9: =IF(A9="","",HYPERLINK("https://calendar.google.com/calendar/render?action=TEMPLATE&text="&"Racksa%3A%20"&SUBSTITUTE(SUBSTITUTE(SUBSTITUTE(LEFT(B9,45),"&","y")," ","%20"),"#","")&"%20-%20seguimiento"&"&dates="&YEAR(IF(O9="",TODAY()+3,O9))&RIGHT("0"&MONTH(IF(O9="",TODAY()+3,O9)),2)&RIGHT("0"&DAY(IF(O9="",TODAY()+3,O9)),2)&"/"&YEAR(IF(O9="",TODAY()+4,O9+1))&RIGHT("0"&MONTH(IF(O9="",TODAY()+4,O9+1)),2)&RIGHT("0"&DAY(IF(O9="",TODAY()+4,O9+1)),2),"📅 Agendar"))
A10: P009 | B10: =IFERROR(INDEX(Prospectos!$F:$F,MATCH(A10,Prospectos!$A:$A,0)),"") | C10: =IFERROR(INDEX(Prospectos!$D:$D,MATCH(A10,Prospectos!$A:$A,0)),"") | D10: =IFERROR(INDEX(Prospectos!$B:$B,MATCH(A10,Prospectos!$A:$A,0)),"") | J10: Por contactar | P10: =IF(L10="","",TODAY()-L10) | T10: ✉️ Abrir correo | U10: ↩️ Seguimiento | V10: =IF(A10="","",HYPERLINK("https://calendar.google.com/calendar/render?action=TEMPLATE&text="&"Racksa%3A%20"&SUBSTITUTE(SUBSTITUTE(SUBSTITUTE(LEFT(B10,45),"&","y")," ","%20"),"#","")&"%20-%20seguimiento"&"&dates="&YEAR(IF(O10="",TODAY()+3,O10))&RIGHT("0"&MONTH(IF(O10="",TODAY()+3,O10)),2)&RIGHT("0"&DAY(IF(O10="",TODAY()+3,O10)),2)&"/"&YEAR(IF(O10="",TODAY()+4,O10+1))&RIGHT("0"&MONTH(IF(O10="",TODAY()+4,O10+1)),2)&RIGHT("0"&DAY(IF(O10="",TODAY()+4,O10+1)),2),"📅 Agendar"))
A11: P010 | B11: =IFERROR(INDEX(Prospectos!$F:$F,MATCH(A11,Prospectos!$A:$A,0)),"") | C11: =IFERROR(INDEX(Prospectos!$D:$D,MATCH(A11,Prospectos!$A:$A,0)),"") | D11: =IFERROR(INDEX(Prospectos!$B:$B,MATCH(A11,Prospectos!$A:$A,0)),"") | H11: info@dipacmanta.com | I11: Correo | J11: Por contactar | P11: =IF(L11="","",TODAY()-L11) | T11: ✉️ Abrir correo | U11: ↩️ Seguimiento | V11: =IF(A11="","",HYPERLINK("https://calendar.google.com/calendar/render?action=TEMPLATE&text="&"Racksa%3A%20"&SUBSTITUTE(SUBSTITUTE(SUBSTITUTE(LEFT(B11,45),"&","y")," ","%20"),"#","")&"%20-%20seguimiento"&"&dates="&YEAR(IF(O11="",TODAY()+3,O11))&RIGHT("0"&MONTH(IF(O11="",TODAY()+3,O11)),2)&RIGHT("0"&DAY(IF(O11="",TODAY()+3,O11)),2)&"/"&YEAR(IF(O11="",TODAY()+4,O11+1))&RIGHT("0"&MONTH(IF(O11="",TODAY()+4,O11+1)),2)&RIGHT("0"&DAY(IF(O11="",TODAY()+4,O11+1)),2),"📅 Agendar"))
A12: P011 | B12: =IFERROR(INDEX(Prospectos!$F:$F,MATCH(A12,Prospectos!$A:$A,0)),"") | C12: =IFERROR(INDEX(Prospectos!$D:$D,MATCH(A12,Prospectos!$A:$A,0)),"") | D12: =IFERROR(INDEX(Prospectos!$B:$B,MATCH(A12,Prospectos!$A:$A,0)),"") | J12: Por contactar | P12: =IF(L12="","",TODAY()-L12) | T12: ✉️ Abrir correo | U12: ↩️ Seguimiento | V12: =IF(A12="","",HYPERLINK("https://calendar.google.com/calendar/render?action=TEMPLATE&text="&"Racksa%3A%20"&SUBSTITUTE(SUBSTITUTE(SUBSTITUTE(LEFT(B12,45),"&","y")," ","%20"),"#","")&"%20-%20seguimiento"&"&dates="&YEAR(IF(O12="",TODAY()+3,O12))&RIGHT("0"&MONTH(IF(O12="",TODAY()+3,O12)),2)&RIGHT("0"&DAY(IF(O12="",TODAY()+3,O12)),2)&"/"&YEAR(IF(O12="",TODAY()+4,O12+1))&RIGHT("0"&MONTH(IF(O12="",TODAY()+4,O12+1)),2)&RIGHT("0"&DAY(IF(O12="",TODAY()+4,O12+1)),2),"📅 Agendar"))
A13: P012 | B13: =IFERROR(INDEX(Prospectos!$F:$F,MATCH(A13,Prospectos!$A:$A,0)),"") | C13: =IFERROR(INDEX(Prospectos!$D:$D,MATCH(A13,Prospectos!$A:$A,0)),"") | D13: =IFERROR(INDEX(Prospectos!$B:$B,MATCH(A13,Prospectos!$A:$A,0)),"") | J13: Por contactar | P13: =IF(L13="","",TODAY()-L13) | T13: ✉️ Abrir correo | U13: ↩️ Seguimiento | V13: =IF(A13="","",HYPERLINK("https://calendar.google.com/calendar/render?action=TEMPLATE&text="&"Racksa%3A%20"&SUBSTITUTE(SUBSTITUTE(SUBSTITUTE(LEFT(B13,45),"&","y")," ","%20"),"#","")&"%20-%20seguimiento"&"&dates="&YEAR(IF(O13="",TODAY()+3,O13))&RIGHT("0"&MONTH(IF(O13="",TODAY()+3,O13)),2)&RIGHT("0"&DAY(IF(O13="",TODAY()+3,O13)),2)&"/"&YEAR(IF(O13="",TODAY()+4,O13+1))&RIGHT("0"&MONTH(IF(O13="",TODAY()+4,O13+1)),2)&RIGHT("0"&DAY(IF(O13="",TODAY()+4,O13+1)),2),"📅 Agendar"))
A14: P013 | B14: =IFERROR(INDEX(Prospectos!$F:$F,MATCH(A14,Prospectos!$A:$A,0)),"") | C14: =IFERROR(INDEX(Prospectos!$D:$D,MATCH(A14,Prospectos!$A:$A,0)),"") | D14: =IFERROR(INDEX(Prospectos!$B:$B,MATCH(A14,Prospectos!$A:$A,0)),"") | J14: Por contactar | P14: =IF(L14="","",TODAY()-L14) | T14: ✉️ Abrir correo | U14: ↩️ Seguimiento | V14: =IF(A14="","",HYPERLINK("https://calendar.google.com/calendar/render?action=TEMPLATE&text="&"Racksa%3A%20"&SUBSTITUTE(SUBSTITUTE(SUBSTITUTE(LEFT(B14,45),"&","y")," ","%20"),"#","")&"%20-%20seguimiento"&"&dates="&YEAR(IF(O14="",TODAY()+3,O14))&RIGHT("0"&MONTH(IF(O14="",TODAY()+3,O14)),2)&RIGHT("0"&DAY(IF(O14="",TODAY()+3,O14)),2)&"/"&YEAR(IF(O14="",TODAY()+4,O14+1))&RIGHT("0"&MONTH(IF(O14="",TODAY()+4,O14+1)),2)&RIGHT("0"&DAY(IF(O14="",TODAY()+4,O14+1)),2),"📅 Agendar"))
A15: P014 | B15: =IFERROR(INDEX(Prospectos!$F:$F,MATCH(A15,Prospectos!$A:$A,0)),"") | C15: =IFERROR(INDEX(Prospectos!$D:$D,MATCH(A15,Prospectos!$A:$A,0)),"") | D15: =IFERROR(INDEX(Prospectos!$B:$B,MATCH(A15,Prospectos!$A:$A,0)),"") | J15: Por contactar | P15: =IF(L15="","",TODAY()-L15) | T15: ✉️ Abrir correo | U15: ↩️ Seguimiento | V15: =IF(A15="","",HYPERLINK("https://calendar.google.com/calendar/render?action=TEMPLATE&text="&"Racksa%3A%20"&SUBSTITUTE(SUBSTITUTE(SUBSTITUTE(LEFT(B15,45),"&","y")," ","%20"),"#","")&"%20-%20seguimiento"&"&dates="&YEAR(IF(O15="",TODAY()+3,O15))&RIGHT("0"&MONTH(IF(O15="",TODAY()+3,O15)),2)&RIGHT("0"&DAY(IF(O15="",TODAY()+3,O15)),2)&"/"&YEAR(IF(O15="",TODAY()+4,O15+1))&RIGHT("0"&MONTH(IF(O15="",TODAY()+4,O15+1)),2)&RIGHT("0"&DAY(IF(O15="",TODAY()+4,O15+1)),2),"📅 Agendar"))
A16: P015 | B16: =IFERROR(INDEX(Prospectos!$F:$F,MATCH(A16,Prospectos!$A:$A,0)),"") | C16: =IFERROR(INDEX(Prospectos!$D:$D,MATCH(A16,Prospectos!$A:$A,0)),"") | D16: =IFERROR(INDEX(Prospectos!$B:$B,MATCH(A16,Prospectos!$A:$A,0)),"") | J16: Por contactar | P16: =IF(L16="","",TODAY()-L16) | T16: ✉️ Abrir correo | U16: ↩️ Seguimiento | V16: =IF(A16="","",HYPERLINK("https://calendar.google.com/calendar/render?action=TEMPLATE&text="&"Racksa%3A%20"&SUBSTITUTE(SUBSTITUTE(SUBSTITUTE(LEFT(B16,45),"&","y")," ","%20"),"#","")&"%20-%20seguimiento"&"&dates="&YEAR(IF(O16="",TODAY()+3,O16))&RIGHT("0"&MONTH(IF(O16="",TODAY()+3,O16)),2)&RIGHT("0"&DAY(IF(O16="",TODAY()+3,O16)),2)&"/"&YEAR(IF(O16="",TODAY()+4,O16+1))&RIGHT("0"&MONTH(IF(O16="",TODAY()+4,O16+1)),2)&RIGHT("0"&DAY(IF(O16="",TODAY()+4,O16+1)),2),"📅 Agendar"))
A17: P016 | B17: =IFERROR(INDEX(Prospectos!$F:$F,MATCH(A17,Prospectos!$A:$A,0)),"") | C17: =IFERROR(INDEX(Prospectos!$D:$D,MATCH(A17,Prospectos!$A:$A,0)),"") | D17: =IFERROR(INDEX(Prospectos!$B:$B,MATCH(A17,Prospectos!$A:$A,0)),"") | J17: Por contactar | P17: =IF(L17="","",TODAY()-L17) | T17: ✉️ Abrir correo | U17: ↩️ Seguimiento | V17: =IF(A17="","",HYPERLINK("https://calendar.google.com/calendar/render?action=TEMPLATE&text="&"Racksa%3A%20"&SUBSTITUTE(SUBSTITUTE(SUBSTITUTE(LEFT(B17,45),"&","y")," ","%20"),"#","")&"%20-%20seguimiento"&"&dates="&YEAR(IF(O17="",TODAY()+3,O17))&RIGHT("0"&MONTH(IF(O17="",TODAY()+3,O17)),2)&RIGHT("0"&DAY(IF(O17="",TODAY()+3,O17)),2)&"/"&YEAR(IF(O17="",TODAY()+4,O17+1))&RIGHT("0"&MONTH(IF(O17="",TODAY()+4,O17+1)),2)&RIGHT("0"&DAY(IF(O17="",TODAY()+4,O17+1)),2),"📅 Agendar"))
A18: P017 | B18: =IFERROR(INDEX(Prospectos!$F:$F,MATCH(A18,Prospectos!$A:$A,0)),"") | C18: =IFERROR(INDEX(Prospectos!$D:$D,MATCH(A18,Prospectos!$A:$A,0)),"") | D18: =IFERROR(INDEX(Prospectos!$B:$B,MATCH(A18,Prospectos!$A:$A,0)),"") | J18: Por contactar | P18: =IF(L18="","",TODAY()-L18) | T18: ✉️ Abrir correo | U18: ↩️ Seguimiento | V18: =IF(A18="","",HYPERLINK("https://calendar.google.com/calendar/render?action=TEMPLATE&text="&"Racksa%3A%20"&SUBSTITUTE(SUBSTITUTE(SUBSTITUTE(LEFT(B18,45),"&","y")," ","%20"),"#","")&"%20-%20seguimiento"&"&dates="&YEAR(IF(O18="",TODAY()+3,O18))&RIGHT("0"&MONTH(IF(O18="",TODAY()+3,O18)),2)&RIGHT("0"&DAY(IF(O18="",TODAY()+3,O18)),2)&"/"&YEAR(IF(O18="",TODAY()+4,O18+1))&RIGHT("0"&MONTH(IF(O18="",TODAY()+4,O18+1)),2)&RIGHT("0"&DAY(IF(O18="",TODAY()+4,O18+1)),2),"📅 Agendar"))
A19: P018 | B19: =IFERROR(INDEX(Prospectos!$F:$F,MATCH(A19,Prospectos!$A:$A,0)),"") | C19: =IFERROR(INDEX(Prospectos!$D:$D,MATCH(A19,Prospectos!$A:$A,0)),"") | D19: =IFERROR(INDEX(Prospectos!$B:$B,MATCH(A19,Prospectos!$A:$A,0)),"") | J19: Por contactar | P19: =IF(L19="","",TODAY()-L19) | T19: ✉️ Abrir correo | U19: ↩️ Seguimiento | V19: =IF(A19="","",HYPERLINK("https://calendar.google.com/calendar/render?action=TEMPLATE&text="&"Racksa%3A%20"&SUBSTITUTE(SUBSTITUTE(SUBSTITUTE(LEFT(B19,45),"&","y")," ","%20"),"#","")&"%20-%20seguimiento"&"&dates="&YEAR(IF(O19="",TODAY()+3,O19))&RIGHT("0"&MONTH(IF(O19="",TODAY()+3,O19)),2)&RIGHT("0"&DAY(IF(O19="",TODAY()+3,O19)),2)&"/"&YEAR(IF(O19="",TODAY()+4,O19+1))&RIGHT("0"&MONTH(IF(O19="",TODAY()+4,O19+1)),2)&RIGHT("0"&DAY(IF(O19="",TODAY()+4,O19+1)),2),"📅 Agendar"))
A20: P019 | B20: =IFERROR(INDEX(Prospectos!$F:$F,MATCH(A20,Prospectos!$A:$A,0)),"") | C20: =IFERROR(INDEX(Prospectos!$D:$D,MATCH(A20,Prospectos!$A:$A,0)),"") | D20: =IFERROR(INDEX(Prospectos!$B:$B,MATCH(A20,Prospectos!$A:$A,0)),"") | H20: ventasgye@novacero.com | I20: Correo | J20: Por contactar | P20: =IF(L20="","",TODAY()-L20) | T20: ✉️ Abrir correo | U20: ↩️ Seguimiento | V20: =IF(A20="","",HYPERLINK("https://calendar.google.com/calendar/render?action=TEMPLATE&text="&"Racksa%3A%20"&SUBSTITUTE(SUBSTITUTE(SUBSTITUTE(LEFT(B20,45),"&","y")," ","%20"),"#","")&"%20-%20seguimiento"&"&dates="&YEAR(IF(O20="",TODAY()+3,O20))&RIGHT("0"&MONTH(IF(O20="",TODAY()+3,O20)),2)&RIGHT("0"&DAY(IF(O20="",TODAY()+3,O20)),2)&"/"&YEAR(IF(O20="",TODAY()+4,O20+1))&RIGHT("0"&MONTH(IF(O20="",TODAY()+4,O20+1)),2)&RIGHT("0"&DAY(IF(O20="",TODAY()+4,O20+1)),2),"📅 Agendar"))
A21: P020 | B21: =IFERROR(INDEX(Prospectos!$F:$F,MATCH(A21,Prospectos!$A:$A,0)),"") | C21: =IFERROR(INDEX(Prospectos!$D:$D,MATCH(A21,Prospectos!$A:$A,0)),"") | D21: =IFERROR(INDEX(Prospectos!$B:$B,MATCH(A21,Prospectos!$A:$A,0)),"") | J21: Por contactar | P21: =IF(L21="","",TODAY()-L21) | T21: ✉️ Abrir correo | U21: ↩️ Seguimiento | V21: =IF(A21="","",HYPERLINK("https://calendar.google.com/calendar/render?action=TEMPLATE&text="&"Racksa%3A%20"&SUBSTITUTE(SUBSTITUTE(SUBSTITUTE(LEFT(B21,45),"&","y")," ","%20"),"#","")&"%20-%20seguimiento"&"&dates="&YEAR(IF(O21="",TODAY()+3,O21))&RIGHT("0"&MONTH(IF(O21="",TODAY()+3,O21)),2)&RIGHT("0"&DAY(IF(O21="",TODAY()+3,O21)),2)&"/"&YEAR(IF(O21="",TODAY()+4,O21+1))&RIGHT("0"&MONTH(IF(O21="",TODAY()+4,O21+1)),2)&RIGHT("0"&DAY(IF(O21="",TODAY()+4,O21+1)),2),"📅 Agendar"))
A22: P021 | B22: =IFERROR(INDEX(Prospectos!$F:$F,MATCH(A22,Prospectos!$A:$A,0)),"") | C22: =IFERROR(INDEX(Prospectos!$D:$D,MATCH(A22,Prospectos!$A:$A,0)),"") | D22: =IFERROR(INDEX(Prospectos!$B:$B,MATCH(A22,Prospectos!$A:$A,0)),"") | J22: Por contactar | P22: =IF(L22="","",TODAY()-L22) | T22: ✉️ Abrir correo | U22: ↩️ Seguimiento | V22: =IF(A22="","",HYPERLINK("https://calendar.google.com/calendar/render?action=TEMPLATE&text="&"Racksa%3A%20"&SUBSTITUTE(SUBSTITUTE(SUBSTITUTE(LEFT(B22,45),"&","y")," ","%20"),"#","")&"%20-%20seguimiento"&"&dates="&YEAR(IF(O22="",TODAY()+3,O22))&RIGHT("0"&MONTH(IF(O22="",TODAY()+3,O22)),2)&RIGHT("0"&DAY(IF(O22="",TODAY()+3,O22)),2)&"/"&YEAR(IF(O22="",TODAY()+4,O22+1))&RIGHT("0"&MONTH(IF(O22="",TODAY()+4,O22+1)),2)&RIGHT("0"&DAY(IF(O22="",TODAY()+4,O22+1)),2),"📅 Agendar"))
A23: P022 | B23: =IFERROR(INDEX(Prospectos!$F:$F,MATCH(A23,Prospectos!$A:$A,0)),"") | C23: =IFERROR(INDEX(Prospectos!$D:$D,MATCH(A23,Prospectos!$A:$A,0)),"") | D23: =IFERROR(INDEX(Prospectos!$B:$B,MATCH(A23,Prospectos!$A:$A,0)),"") | J23: Por contactar | P23: =IF(L23="","",TODAY()-L23) | T23: ✉️ Abrir correo | U23: ↩️ Seguimiento | V23: =IF(A23="","",HYPERLINK("https://calendar.google.com/calendar/render?action=TEMPLATE&text="&"Racksa%3A%20"&SUBSTITUTE(SUBSTITUTE(SUBSTITUTE(LEFT(B23,45),"&","y")," ","%20"),"#","")&"%20-%20seguimiento"&"&dates="&YEAR(IF(O23="",TODAY()+3,O23))&RIGHT("0"&MONTH(IF(O23="",TODAY()+3,O23)),2)&RIGHT("0"&DAY(IF(O23="",TODAY()+3,O23)),2)&"/"&YEAR(IF(O23="",TODAY()+4,O23+1))&RIGHT("0"&MONTH(IF(O23="",TODAY()+4,O23+1)),2)&RIGHT("0"&DAY(IF(O23="",TODAY()+4,O23+1)),2),"📅 Agendar"))
A24: P023 | B24: =IFERROR(INDEX(Prospectos!$F:$F,MATCH(A24,Prospectos!$A:$A,0)),"") | C24: =IFERROR(INDEX(Prospectos!$D:$D,MATCH(A24,Prospectos!$A:$A,0)),"") | D24: =IFERROR(INDEX(Prospectos!$B:$B,MATCH(A24,Prospectos!$A:$A,0)),"") | H24: servicioalcliente@farmaenlace.com | I24: Correo | J24: Por contactar | P24: =IF(L24="","",TODAY()-L24) | T24: ✉️ Abrir correo | U24: ↩️ Seguimiento | V24: =IF(A24="","",HYPERLINK("https://calendar.google.com/calendar/render?action=TEMPLATE&text="&"Racksa%3A%20"&SUBSTITUTE(SUBSTITUTE(SUBSTITUTE(LEFT(B24,45),"&","y")," ","%20"),"#","")&"%20-%20seguimiento"&"&dates="&YEAR(IF(O24="",TODAY()+3,O24))&RIGHT("0"&MONTH(IF(O24="",TODAY()+3,O24)),2)&RIGHT("0"&DAY(IF(O24="",TODAY()+3,O24)),2)&"/"&YEAR(IF(O24="",TODAY()+4,O24+1))&RIGHT("0"&MONTH(IF(O24="",TODAY()+4,O24+1)),2)&RIGHT("0"&DAY(IF(O24="",TODAY()+4,O24+1)),2),"📅 Agendar"))
A25: P024 | B25: =IFERROR(INDEX(Prospectos!$F:$F,MATCH(A25,Prospectos!$A:$A,0)),"") | C25: =IFERROR(INDEX(Prospectos!$D:$D,MATCH(A25,Prospectos!$A:$A,0)),"") | D25: =IFERROR(INDEX(Prospectos!$B:$B,MATCH(A25,Prospectos!$A:$A,0)),"") | J25: Por contactar | P25: =IF(L25="","",TODAY()-L25) | T25: ✉️ Abrir correo | U25: ↩️ Seguimiento | V25: =IF(A25="","",HYPERLINK("https://calendar.google.com/calendar/render?action=TEMPLATE&text="&"Racksa%3A%20"&SUBSTITUTE(SUBSTITUTE(SUBSTITUTE(LEFT(B25,45),"&","y")," ","%20"),"#","")&"%20-%20seguimiento"&"&dates="&YEAR(IF(O25="",TODAY()+3,O25))&RIGHT("0"&MONTH(IF(O25="",TODAY()+3,O25)),2)&RIGHT("0"&DAY(IF(O25="",TODAY()+3,O25)),2)&"/"&YEAR(IF(O25="",TODAY()+4,O25+1))&RIGHT("0"&MONTH(IF(O25="",TODAY()+4,O25+1)),2)&RIGHT("0"&DAY(IF(O25="",TODAY()+4,O25+1)),2),"📅 Agendar"))
A26: P025 | B26: =IFERROR(INDEX(Prospectos!$F:$F,MATCH(A26,Prospectos!$A:$A,0)),"") | C26: =IFERROR(INDEX(Prospectos!$D:$D,MATCH(A26,Prospectos!$A:$A,0)),"") | D26: =IFERROR(INDEX(Prospectos!$B:$B,MATCH(A26,Prospectos!$A:$A,0)),"") | J26: Por contactar | P26: =IF(L26="","",TODAY()-L26) | T26: ✉️ Abrir correo | U26: ↩️ Seguimiento | V26: =IF(A26="","",HYPERLINK("https://calendar.google.com/calendar/render?action=TEMPLATE&text="&"Racksa%3A%20"&SUBSTITUTE(SUBSTITUTE(SUBSTITUTE(LEFT(B26,45),"&","y")," ","%20"),"#","")&"%20-%20seguimiento"&"&dates="&YEAR(IF(O26="",TODAY()+3,O26))&RIGHT("0"&MONTH(IF(O26="",TODAY()+3,O26)),2)&RIGHT("0"&DAY(IF(O26="",TODAY()+3,O26)),2)&"/"&YEAR(IF(O26="",TODAY()+4,O26+1))&RIGHT("0"&MONTH(IF(O26="",TODAY()+4,O26+1)),2)&RIGHT("0"&DAY(IF(O26="",TODAY()+4,O26+1)),2),"📅 Agendar"))
A27: P026 | B27: =IFERROR(INDEX(Prospectos!$F:$F,MATCH(A27,Prospectos!$A:$A,0)),"") | C27: =IFERROR(INDEX(Prospectos!$D:$D,MATCH(A27,Prospectos!$A:$A,0)),"") | D27: =IFERROR(INDEX(Prospectos!$B:$B,MATCH(A27,Prospectos!$A:$A,0)),"") | J27: Por contactar | P27: =IF(L27="","",TODAY()-L27) | T27: ✉️ Abrir correo | U27: ↩️ Seguimiento | V27: =IF(A27="","",HYPERLINK("https://calendar.google.com/calendar/render?action=TEMPLATE&text="&"Racksa%3A%20"&SUBSTITUTE(SUBSTITUTE(SUBSTITUTE(LEFT(B27,45),"&","y")," ","%20"),"#","")&"%20-%20seguimiento"&"&dates="&YEAR(IF(O27="",TODAY()+3,O27))&RIGHT("0"&MONTH(IF(O27="",TODAY()+3,O27)),2)&RIGHT("0"&DAY(IF(O27="",TODAY()+3,O27)),2)&"/"&YEAR(IF(O27="",TODAY()+4,O27+1))&RIGHT("0"&MONTH(IF(O27="",TODAY()+4,O27+1)),2)&RIGHT("0"&DAY(IF(O27="",TODAY()+4,O27+1)),2),"📅 Agendar"))
A28: P027 | B28: =IFERROR(INDEX(Prospectos!$F:$F,MATCH(A28,Prospectos!$A:$A,0)),"") | C28: =IFERROR(INDEX(Prospectos!$D:$D,MATCH(A28,Prospectos!$A:$A,0)),"") | D28: =IFERROR(INDEX(Prospectos!$B:$B,MATCH(A28,Prospectos!$A:$A,0)),"") | H28: comunicaciones@quifatex.com | I28: Correo | J28: Por contactar | P28: =IF(L28="","",TODAY()-L28) | T28: ✉️ Abrir correo | U28: ↩️ Seguimiento | V28: =IF(A28="","",HYPERLINK("https://calendar.google.com/calendar/render?action=TEMPLATE&text="&"Racksa%3A%20"&SUBSTITUTE(SUBSTITUTE(SUBSTITUTE(LEFT(B28,45),"&","y")," ","%20"),"#","")&"%20-%20seguimiento"&"&dates="&YEAR(IF(O28="",TODAY()+3,O28))&RIGHT("0"&MONTH(IF(O28="",TODAY()+3,O28)),2)&RIGHT("0"&DAY(IF(O28="",TODAY()+3,O28)),2)&"/"&YEAR(IF(O28="",TODAY()+4,O28+1))&RIGHT("0"&MONTH(IF(O28="",TODAY()+4,O28+1)),2)&RIGHT("0"&DAY(IF(O28="",TODAY()+4,O28+1)),2),"📅 Agendar"))
A29: P028 | B29: =IFERROR(INDEX(Prospectos!$F:$F,MATCH(A29,Prospectos!$A:$A,0)),"") | C29: =IFERROR(INDEX(Prospectos!$D:$D,MATCH(A29,Prospectos!$A:$A,0)),"") | D29: =IFERROR(INDEX(Prospectos!$B:$B,MATCH(A29,Prospectos!$A:$A,0)),"") | J29: Por contactar | P29: =IF(L29="","",TODAY()-L29) | T29: ✉️ Abrir correo | U29: ↩️ Seguimiento | V29: =IF(A29="","",HYPERLINK("https://calendar.google.com/calendar/render?action=TEMPLATE&text="&"Racksa%3A%20"&SUBSTITUTE(SUBSTITUTE(SUBSTITUTE(LEFT(B29,45),"&","y")," ","%20"),"#","")&"%20-%20seguimiento"&"&dates="&YEAR(IF(O29="",TODAY()+3,O29))&RIGHT("0"&MONTH(IF(O29="",TODAY()+3,O29)),2)&RIGHT("0"&DAY(IF(O29="",TODAY()+3,O29)),2)&"/"&YEAR(IF(O29="",TODAY()+4,O29+1))&RIGHT("0"&MONTH(IF(O29="",TODAY()+4,O29+1)),2)&RIGHT("0"&DAY(IF(O29="",TODAY()+4,O29+1)),2),"📅 Agendar"))
A30: P029 | B30: =IFERROR(INDEX(Prospectos!$F:$F,MATCH(A30,Prospectos!$A:$A,0)),"") | C30: =IFERROR(INDEX(Prospectos!$D:$D,MATCH(A30,Prospectos!$A:$A,0)),"") | D30: =IFERROR(INDEX(Prospectos!$B:$B,MATCH(A30,Prospectos!$A:$A,0)),"") | H30: info@megaprofer.com | I30: Correo | J30: Por contactar | P30: =IF(L30="","",TODAY()-L30) | T30: ✉️ Abrir correo | U30: ↩️ Seguimiento | V30: =IF(A30="","",HYPERLINK("https://calendar.google.com/calendar/render?action=TEMPLATE&text="&"Racksa%3A%20"&SUBSTITUTE(SUBSTITUTE(SUBSTITUTE(LEFT(B30,45),"&","y")," ","%20"),"#","")&"%20-%20seguimiento"&"&dates="&YEAR(IF(O30="",TODAY()+3,O30))&RIGHT("0"&MONTH(IF(O30="",TODAY()+3,O30)),2)&RIGHT("0"&DAY(IF(O30="",TODAY()+3,O30)),2)&"/"&YEAR(IF(O30="",TODAY()+4,O30+1))&RIGHT("0"&MONTH(IF(O30="",TODAY()+4,O30+1)),2)&RIGHT("0"&DAY(IF(O30="",TODAY()+4,O30+1)),2),"📅 Agendar"))
A31: P030 | B31: =IFERROR(INDEX(Prospectos!$F:$F,MATCH(A31,Prospectos!$A:$A,0)),"") | C31: =IFERROR(INDEX(Prospectos!$D:$D,MATCH(A31,Prospectos!$A:$A,0)),"") | D31: =IFERROR(INDEX(Prospectos!$B:$B,MATCH(A31,Prospectos!$A:$A,0)),"") | J31: Por contactar | P31: =IF(L31="","",TODAY()-L31) | T31: ✉️ Abrir correo | U31: ↩️ Seguimiento | V31: =IF(A31="","",HYPERLINK("https://calendar.google.com/calendar/render?action=TEMPLATE&text="&"Racksa%3A%20"&SUBSTITUTE(SUBSTITUTE(SUBSTITUTE(LEFT(B31,45),"&","y")," ","%20"),"#","")&"%20-%20seguimiento"&"&dates="&YEAR(IF(O31="",TODAY()+3,O31))&RIGHT("0"&MONTH(IF(O31="",TODAY()+3,O31)),2)&RIGHT("0"&DAY(IF(O31="",TODAY()+3,O31)),2)&"/"&YEAR(IF(O31="",TODAY()+4,O31+1))&RIGHT("0"&MONTH(IF(O31="",TODAY()+4,O31+1)),2)&RIGHT("0"&DAY(IF(O31="",TODAY()+4,O31+1)),2),"📅 Agendar"))
A32: P031 | B32: =IFERROR(INDEX(Prospectos!$F:$F,MATCH(A32,Prospectos!$A:$A,0)),"") | C32: =IFERROR(INDEX(Prospectos!$D:$D,MATCH(A32,Prospectos!$A:$A,0)),"") | D32: =IFERROR(INDEX(Prospectos!$B:$B,MATCH(A32,Prospectos!$A:$A,0)),"") | J32: Por contactar | P32: =IF(L32="","",TODAY()-L32) | T32: ✉️ Abrir correo | U32: ↩️ Seguimiento | V32: =IF(A32="","",HYPERLINK("https://calendar.google.com/calendar/render?action=TEMPLATE&text="&"Racksa%3A%20"&SUBSTITUTE(SUBSTITUTE(SUBSTITUTE(LEFT(B32,45),"&","y")," ","%20"),"#","")&"%20-%20seguimiento"&"&dates="&YEAR(IF(O32="",TODAY()+3,O32))&RIGHT("0"&MONTH(IF(O32="",TODAY()+3,O32)),2)&RIGHT("0"&DAY(IF(O32="",TODAY()+3,O32)),2)&"/"&YEAR(IF(O32="",TODAY()+4,O32+1))&RIGHT("0"&MONTH(IF(O32="",TODAY()+4,O32+1)),2)&RIGHT("0"&DAY(IF(O32="",TODAY()+4,O32+1)),2),"📅 Agendar"))
A33: P032 | B33: =IFERROR(INDEX(Prospectos!$F:$F,MATCH(A33,Prospectos!$A:$A,0)),"") | C33: =IFERROR(INDEX(Prospectos!$D:$D,MATCH(A33,Prospectos!$A:$A,0)),"") | D33: =IFERROR(INDEX(Prospectos!$B:$B,MATCH(A33,Prospectos!$A:$A,0)),"") | J33: Por contactar | P33: =IF(L33="","",TODAY()-L33) | T33: ✉️ Abrir correo | U33: ↩️ Seguimiento | V33: =IF(A33="","",HYPERLINK("https://calendar.google.com/calendar/render?action=TEMPLATE&text="&"Racksa%3A%20"&SUBSTITUTE(SUBSTITUTE(SUBSTITUTE(LEFT(B33,45),"&","y")," ","%20"),"#","")&"%20-%20seguimiento"&"&dates="&YEAR(IF(O33="",TODAY()+3,O33))&RIGHT("0"&MONTH(IF(O33="",TODAY()+3,O33)),2)&RIGHT("0"&DAY(IF(O33="",TODAY()+3,O33)),2)&"/"&YEAR(IF(O33="",TODAY()+4,O33+1))&RIGHT("0"&MONTH(IF(O33="",TODAY()+4,O33+1)),2)&RIGHT("0"&DAY(IF(O33="",TODAY()+4,O33+1)),2),"📅 Agendar"))
A34: P033 | B34: =IFERROR(INDEX(Prospectos!$F:$F,MATCH(A34,Prospectos!$A:$A,0)),"") | C34: =IFERROR(INDEX(Prospectos!$D:$D,MATCH(A34,Prospectos!$A:$A,0)),"") | D34: =IFERROR(INDEX(Prospectos!$B:$B,MATCH(A34,Prospectos!$A:$A,0)),"") | J34: Por contactar | P34: =IF(L34="","",TODAY()-L34) | T34: ✉️ Abrir correo | U34: ↩️ Seguimiento | V34: =IF(A34="","",HYPERLINK("https://calendar.google.com/calendar/render?action=TEMPLATE&text="&"Racksa%3A%20"&SUBSTITUTE(SUBSTITUTE(SUBSTITUTE(LEFT(B34,45),"&","y")," ","%20"),"#","")&"%20-%20seguimiento"&"&dates="&YEAR(IF(O34="",TODAY()+3,O34))&RIGHT("0"&MONTH(IF(O34="",TODAY()+3,O34)),2)&RIGHT("0"&DAY(IF(O34="",TODAY()+3,O34)),2)&"/"&YEAR(IF(O34="",TODAY()+4,O34+1))&RIGHT("0"&MONTH(IF(O34="",TODAY()+4,O34+1)),2)&RIGHT("0"&DAY(IF(O34="",TODAY()+4,O34+1)),2),"📅 Agendar"))
A35: P034 | B35: =IFERROR(INDEX(Prospectos!$F:$F,MATCH(A35,Prospectos!$A:$A,0)),"") | C35: =IFERROR(INDEX(Prospectos!$D:$D,MATCH(A35,Prospectos!$A:$A,0)),"") | D35: =IFERROR(INDEX(Prospectos!$B:$B,MATCH(A35,Prospectos!$A:$A,0)),"") | J35: Por contactar | P35: =IF(L35="","",TODAY()-L35) | T35: ✉️ Abrir correo | U35: ↩️ Seguimiento | V35: =IF(A35="","",HYPERLINK("https://calendar.google.com/calendar/render?action=TEMPLATE&text="&"Racksa%3A%20"&SUBSTITUTE(SUBSTITUTE(SUBSTITUTE(LEFT(B35,45),"&","y")," ","%20"),"#","")&"%20-%20seguimiento"&"&dates="&YEAR(IF(O35="",TODAY()+3,O35))&RIGHT("0"&MONTH(IF(O35="",TODAY()+3,O35)),2)&RIGHT("0"&DAY(IF(O35="",TODAY()+3,O35)),2)&"/"&YEAR(IF(O35="",TODAY()+4,O35+1))&RIGHT("0"&MONTH(IF(O35="",TODAY()+4,O35+1)),2)&RIGHT("0"&DAY(IF(O35="",TODAY()+4,O35+1)),2),"📅 Agendar"))
A36: P035 | B36: =IFERROR(INDEX(Prospectos!$F:$F,MATCH(A36,Prospectos!$A:$A,0)),"") | C36: =IFERROR(INDEX(Prospectos!$D:$D,MATCH(A36,Prospectos!$A:$A,0)),"") | D36: =IFERROR(INDEX(Prospectos!$B:$B,MATCH(A36,Prospectos!$A:$A,0)),"") | J36: Por contactar | P36: =IF(L36="","",TODAY()-L36) | T36: ✉️ Abrir correo | U36: ↩️ Seguimiento | V36: =IF(A36="","",HYPERLINK("https://calendar.google.com/calendar/render?action=TEMPLATE&text="&"Racksa%3A%20"&SUBSTITUTE(SUBSTITUTE(SUBSTITUTE(LEFT(B36,45),"&","y")," ","%20"),"#","")&"%20-%20seguimiento"&"&dates="&YEAR(IF(O36="",TODAY()+3,O36))&RIGHT("0"&MONTH(IF(O36="",TODAY()+3,O36)),2)&RIGHT("0"&DAY(IF(O36="",TODAY()+3,O36)),2)&"/"&YEAR(IF(O36="",TODAY()+4,O36+1))&RIGHT("0"&MONTH(IF(O36="",TODAY()+4,O36+1)),2)&RIGHT("0"&DAY(IF(O36="",TODAY()+4,O36+1)),2),"📅 Agendar"))
A37: P036 | B37: =IFERROR(INDEX(Prospectos!$F:$F,MATCH(A37,Prospectos!$A:$A,0)),"") | C37: =IFERROR(INDEX(Prospectos!$D:$D,MATCH(A37,Prospectos!$A:$A,0)),"") | D37: =IFERROR(INDEX(Prospectos!$B:$B,MATCH(A37,Prospectos!$A:$A,0)),"") | J37: Por contactar | P37: =IF(L37="","",TODAY()-L37) | T37: ✉️ Abrir correo | U37: ↩️ Seguimiento | V37: =IF(A37="","",HYPERLINK("https://calendar.google.com/calendar/render?action=TEMPLATE&text="&"Racksa%3A%20"&SUBSTITUTE(SUBSTITUTE(SUBSTITUTE(LEFT(B37,45),"&","y")," ","%20"),"#","")&"%20-%20seguimiento"&"&dates="&YEAR(IF(O37="",TODAY()+3,O37))&RIGHT("0"&MONTH(IF(O37="",TODAY()+3,O37)),2)&RIGHT("0"&DAY(IF(O37="",TODAY()+3,O37)),2)&"/"&YEAR(IF(O37="",TODAY()+4,O37+1))&RIGHT("0"&MONTH(IF(O37="",TODAY()+4,O37+1)),2)&RIGHT("0"&DAY(IF(O37="",TODAY()+4,O37+1)),2),"📅 Agendar"))
A38: P037 | B38: =IFERROR(INDEX(Prospectos!$F:$F,MATCH(A38,Prospectos!$A:$A,0)),"") | C38: =IFERROR(INDEX(Prospectos!$D:$D,MATCH(A38,Prospectos!$A:$A,0)),"") | D38: =IFERROR(INDEX(Prospectos!$B:$B,MATCH(A38,Prospectos!$A:$A,0)),"") | J38: Por contactar | P38: =IF(L38="","",TODAY()-L38) | T38: ✉️ Abrir correo | U38: ↩️ Seguimiento | V38: =IF(A38="","",HYPERLINK("https://calendar.google.com/calendar/render?action=TEMPLATE&text="&"Racksa%3A%20"&SUBSTITUTE(SUBSTITUTE(SUBSTITUTE(LEFT(B38,45),"&","y")," ","%20"),"#","")&"%20-%20seguimiento"&"&dates="&YEAR(IF(O38="",TODAY()+3,O38))&RIGHT("0"&MONTH(IF(O38="",TODAY()+3,O38)),2)&RIGHT("0"&DAY(IF(O38="",TODAY()+3,O38)),2)&"/"&YEAR(IF(O38="",TODAY()+4,O38+1))&RIGHT("0"&MONTH(IF(O38="",TODAY()+4,O38+1)),2)&RIGHT("0"&DAY(IF(O38="",TODAY()+4,O38+1)),2),"📅 Agendar"))
A39: P038 | B39: =IFERROR(INDEX(Prospectos!$F:$F,MATCH(A39,Prospectos!$A:$A,0)),"") | C39: =IFERROR(INDEX(Prospectos!$D:$D,MATCH(A39,Prospectos!$A:$A,0)),"") | D39: =IFERROR(INDEX(Prospectos!$B:$B,MATCH(A39,Prospectos!$A:$A,0)),"") | J39: Por contactar | P39: =IF(L39="","",TODAY()-L39) | T39: ✉️ Abrir correo | U39: ↩️ Seguimiento | V39: =IF(A39="","",HYPERLINK("https://calendar.google.com/calendar/render?action=TEMPLATE&text="&"Racksa%3A%20"&SUBSTITUTE(SUBSTITUTE(SUBSTITUTE(LEFT(B39,45),"&","y")," ","%20"),"#","")&"%20-%20seguimiento"&"&dates="&YEAR(IF(O39="",TODAY()+3,O39))&RIGHT("0"&MONTH(IF(O39="",TODAY()+3,O39)),2)&RIGHT("0"&DAY(IF(O39="",TODAY()+3,O39)),2)&"/"&YEAR(IF(O39="",TODAY()+4,O39+1))&RIGHT("0"&MONTH(IF(O39="",TODAY()+4,O39+1)),2)&RIGHT("0"&DAY(IF(O39="",TODAY()+4,O39+1)),2),"📅 Agendar"))
A40: P039 | B40: =IFERROR(INDEX(Prospectos!$F:$F,MATCH(A40,Prospectos!$A:$A,0)),"") | C40: =IFERROR(INDEX(Prospectos!$D:$D,MATCH(A40,Prospectos!$A:$A,0)),"") | D40: =IFERROR(INDEX(Prospectos!$B:$B,MATCH(A40,Prospectos!$A:$A,0)),"") | J40: Por contactar | P40: =IF(L40="","",TODAY()-L40) | T40: ✉️ Abrir correo | U40: ↩️ Seguimiento | V40: =IF(A40="","",HYPERLINK("https://calendar.google.com/calendar/render?action=TEMPLATE&text="&"Racksa%3A%20"&SUBSTITUTE(SUBSTITUTE(SUBSTITUTE(LEFT(B40,45),"&","y")," ","%20"),"#","")&"%20-%20seguimiento"&"&dates="&YEAR(IF(O40="",TODAY()+3,O40))&RIGHT("0"&MONTH(IF(O40="",TODAY()+3,O40)),2)&RIGHT("0"&DAY(IF(O40="",TODAY()+3,O40)),2)&"/"&YEAR(IF(O40="",TODAY()+4,O40+1))&RIGHT("0"&MONTH(IF(O40="",TODAY()+4,O40+1)),2)&RIGHT("0"&DAY(IF(O40="",TODAY()+4,O40+1)),2),"📅 Agendar"))
...

Sheet Listas
A1: Por contactar | B1: LinkedIn
A2: Contactado | B2: WhatsApp
A3: Respondió / interesado | B3: Correo
A4: Visita agendada | B4: Llamada
A5: Levantamiento en bodega | B5: Visita
A6: Proforma enviada | B6: Referido
A7: Negociación | B7: Feria
A8: Ganado
A9: Perdido / sin respuesta
A10: No aplica

Sheet Mensajes
A1: Grupo de mensaje | B1: Canal | C1: Asunto (correo) | D1: Mensaje (reemplaza [Nombre], [Empresa], [Ciudad]) | E1: Seguimiento 1 (a los 3 días hábiles) | F1: Último seguimiento (a los 7 días hábiles)
A2: Retail y supermercados | B2: LinkedIn | C2: — | D2: Hola [Nombre], soy Hansell Moreira de Racksa Ecuador. Diseñamos e instalamos racks y perchas para bodegas en todo el país. Me gustaría conectar y compartirle ideas para el centro de distribución y las bodegas de tiendas. | E2: Gracias por conectar, [Nombre]. En Racksa Ecuador ayudamos a ordenar el CD por pallets y el picking por unidades: rack selectivo con acceso 100% directo a cada pallet y perchas de picking de 500 kg por nivel. Contamos con el stock para entrega inmediata y trabajamos a nivel nacional. ¿Le parece si coordinamos una visita sin costo a su bodega en [Ciudad] para proponerle una distribución? Hansell Moreira · Racksa Ecuador 📱 Mi contacto directo: 099 399 9091 📞 099 182 0185 📞 093 995 7939 📩 proyectos@racksaecuador.com.ec 🌐 https://www.racksaecuador.com.ec | F2: —
A3: Retail y supermercados | B3: WhatsApp | C3: — | D3: Buenos días, [Nombre]. Le saluda Hansell Moreira de *Racksa Ecuador*. Trabajamos con empresas de todo el país para ordenar el CD por pallets y el picking por unidades. ✅ Rack selectivo con acceso 100% directo a cada pallet y perchas de picking de 500 kg por nivel ✅ Contamos con el stock para entrega inmediata ✅ Trabajamos a nivel nacional, también en [Ciudad] 💡 ¿Podemos agendar una visita para revisar el centro de distribución y las bodegas de tiendas de [Empresa]? La propuesta de distribución no tiene costo. Hansell Moreira · Racksa Ecuador 📱 *Mi contacto directo: 099 399 9091* 📞 099 182 0185 📞 093 995 7939 📩 proyectos@racksaecuador.com.ec 🌐 https://www.racksaecuador.com.ec | E3: Hola [Nombre], le escribo para dar seguimiento a mi mensaje sobre los racks y perchas para su bodega. Si me comparte las medidas aproximadas (largo, ancho y alto) le envío una propuesta de distribución. ¡Gracias! Racksa Ecuador · 099 182 0185 | F3: —
A4: Retail y supermercados | B4: Correo | C4: Propuesta de racks y perchas para [Empresa] · Racksa Ecuador | D4: Estimado/a [Nombre]: Le saluda Hansell Moreira, de Racksa Ecuador, empresa de ingeniería intralogística que diseña e instala racks, perchas y mezzanines para bodegas a nivel nacional. Le escribo porque podemos ayudar a [Empresa] a ordenar el CD por pallets y el picking por unidades. Algunos datos de nuestro sistema: • Rack selectivo con acceso 100% directo a cada pallet y perchas de picking de 500 kg por nivel. • Acero Q235B (equivalente ASTM A36) con pintura electrostática epoxi en polvo. • Diseño basado en ANSI/RMI MH16.1, AISI S100 y NEC-SE (incluye sismo). • Contamos con el stock para entrega inmediata. Le propongo una visita técnica sin costo a el centro de distribución y las bodegas de tiendas de [Empresa] en [Ciudad] para levantar medidas y enviarle una distribución con su proforma. ¿Qué día de esta o la próxima semana le acomoda? Atentamente, Hansell Moreira Racksa Ecuador · Ingeniería Intralogística 📱 MI CONTACTO DIRECTO: 099 399 9091 Oficina: 099 182 0185 · 093 995 7939 proyectos@racksaecuador.com.ec https://www.racksaecuador.com.ec | E4: Estimado/a [Nombre]: Le escribo para dar seguimiento a mi correo anterior. Si le resulta más fácil, puede enviarme un plano o las medidas de la bodega y el tipo de carga (pallets, cajas o sacos) y le preparo una propuesta de distribución sin compromiso. Atentamente, Hansell Moreira Racksa Ecuador · Ingeniería Intralogística 📱 MI CONTACTO DIRECTO: 099 399 9091 Oficina: 099 182 0185 · 093 995 7939 proyectos@racksaecuador.com.ec https://www.racksaecuador.com.ec | F4: Estimado/a [Nombre]: Le escribo por última vez para no llenar su bandeja. Si en algún momento [Empresa] necesita ordenar o ampliar su bodega, con gusto le visitamos en [Ciudad] sin costo. Basta con responder este correo o llamarnos. Atentamente, Hansell Moreira Racksa Ecuador · Ingeniería Intralogística 📱 MI CONTACTO DIRECTO: 099 399 9091 Oficina: 099 182 0185 · 093 995 7939 proyectos@racksaecuador.com.ec https://www.racksaecuador.com.ec
A5: Farmacéutica | B5: LinkedIn | C5: — | D5: Hola [Nombre], soy Hansell Moreira de Racksa Ecuador. Diseñamos e instalamos racks y perchas para bodegas en todo el país. Me gustaría conectar y compartirle ideas para la bodega y el centro de distribución. | E5: Gracias por conectar, [Nombre]. En Racksa Ecuador ayudamos a un picking más rápido y ordenado por lote y referencia: perchas de picking de 500 kg por nivel y rack selectivo con acceso 100% directo a cada pallet. Contamos con el stock para entrega inmediata y trabajamos a nivel nacional. ¿Le parece si coordinamos una visita sin costo a su bodega en [Ciudad] para proponerle una distribución? Hansell Moreira · Racksa Ecuador 📱 Mi contacto directo: 099 399 9091 📞 099 182 0185 📞 093 995 7939 📩 proyectos@racksaecuador.com.ec 🌐 https://www.racksaecuador.com.ec | F5: —
A6: Farmacéutica | B6: WhatsApp | C6: — | D6: Buenos días, [Nombre]. Le saluda Hansell Moreira de *Racksa Ecuador*. Trabajamos con empresas de todo el país para un picking más rápido y ordenado por lote y referencia. ✅ Perchas de picking de 500 kg por nivel y rack selectivo con acceso 100% directo a cada pallet ✅ Contamos con el stock para entrega inmediata ✅ Trabajamos a nivel nacional, también en [Ciudad] 💡 ¿Podemos agendar una visita para revisar la bodega y el centro de distribución de [Empresa]? La propuesta de distribución no tiene costo. Hansell Moreira · Racksa Ecuador 📱 *Mi contacto directo: 099 399 9091* 📞 099 182 0185 📞 093 995 7939 📩 proyectos@racksaecuador.com.ec 🌐 https://www.racksaecuador.com.ec | E6: Hola [Nombre], le escribo para dar seguimiento a mi mensaje sobre los racks y perchas para su bodega. Si me comparte las medidas aproximadas (largo, ancho y alto) le envío una propuesta de distribución. ¡Gracias! Racksa Ecuador · 099 182 0185 | F6: —
A7: Farmacéutica | B7: Correo | C7: Propuesta de racks y perchas para [Empresa] · Racksa Ecuador | D7: Estimado/a [Nombre]: Le saluda Hansell Moreira, de Racksa Ecuador, empresa de ingeniería intralogística que diseña e instala racks, perchas y mezzanines para bodegas a nivel nacional. Le escribo porque podemos ayudar a [Empresa] a un picking más rápido y ordenado por lote y referencia. Algunos datos de nuestro sistema: • Perchas de picking de 500 kg por nivel y rack selectivo con acceso 100% directo a cada pallet. • Acero Q235B (equivalente ASTM A36) con pintura electrostática epoxi en polvo. • Diseño basado en ANSI/RMI MH16.1, AISI S100 y NEC-SE (incluye sismo). • Contamos con el stock para entrega inmediata. Le propongo una visita técnica sin costo a la bodega y el centro de distribución de [Empresa] en [Ciudad] para levantar medidas y enviarle una distribución con su proforma. ¿Qué día de esta o la próxima semana le acomoda? Atentamente, Hansell Moreira Racksa Ecuador · Ingeniería Intralogística 📱 MI CONTACTO DIRECTO: 099 399 9091 Oficina: 099 182 0185 · 093 995 7939 proyectos@racksaecuador.com.ec https://www.racksaecuador.com.ec | E7: Estimado/a [Nombre]: Le escribo para dar seguimiento a mi correo anterior. Si le resulta más fácil, puede enviarme un plano o las medidas de la bodega y el tipo de carga (pallets, cajas o sacos) y le preparo una propuesta de distribución sin compromiso. Atentamente, Hansell Moreira Racksa Ecuador · Ingeniería Intralogística 📱 MI CONTACTO DIRECTO: 099 399 9091 Oficina: 099 182 0185 · 093 995 7939 proyectos@racksaecuador.com.ec https://www.racksaecuador.com.ec | F7: Estimado/a [Nombre]: Le escribo por última vez para no llenar su bandeja. Si en algún momento [Empresa] necesita ordenar o ampliar su bodega, con gusto le visitamos en [Ciudad] sin costo. Basta con responder este correo o llamarnos. Atentamente, Hansell Moreira Racksa Ecuador · Ingeniería Intralogística 📱 MI CONTACTO DIRECTO: 099 399 9091 Oficina: 099 182 0185 · 093 995 7939 proyectos@racksaecuador.com.ec https://www.racksaecuador.com.ec
A8: Ferretería, acero y construcción | B8: LinkedIn | C8: — | D8: Hola [Nombre], soy Hansell Moreira de Racksa Ecuador. Diseñamos e instalamos racks y perchas para bodegas en todo el país. Me gustaría conectar y compartirle ideas para las bodegas. | E8: Gracias por conectar, [Nombre]. En Racksa Ecuador ayudamos a aprovechar la altura y tener cada producto a la mano: rack selectivo para 2.000 kg por nivel (2 pallets de 1.000 kg), acero Q235B y pintura electrostática epoxi. Contamos con el stock para entrega inmediata y trabajamos a nivel nacional. ¿Le parece si coordinamos una visita sin costo a su bodega en [Ciudad] para proponerle una distribución? Hansell Moreira · Racksa Ecuador 📱 Mi contacto directo: 099 399 9091 📞 099 182 0185 📞 093 995 7939 📩 proyectos@racksaecuador.com.ec 🌐 https://www.racksaecuador.com.ec | F8: —
